<?xml version="1.0"?>
<robot name="urdfbot">

    <material name="blue">
        <color rgba="0.006 0.151 0.581 1"/>
    </material>

    <material name="white">
        <color rgba="1.0 0.91 0.827 1"/>
    </material>

        
  <link name="base_link">
    <visual>        
      <geometry>
        <box size="0.1 0.1 0.1"/>
      </geometry>
      <material name="white"/>
    </visual>
  </link>

  <link name="head_link">
    <visual>
    <origin rpy="0 0 0" xyz="0 0 0.1" />
      <geometry>
        <box size="0.1 0.1 0.1"/>
      </geometry>
      <material name="blue"/>
    </visual>
  </link>

    <joint name="base_link_to_head_link_joint" type="revolute">
        <origin xyz="0 0 0.11" rpy="0 0 0"/>
        <parent link="base_link"/>
        <child link="head_link"/>
        <axis xyz="0 0 1"/>
        <limit effort="100" velocity="1.0" lower="-1.57" upper="1.57"/>
    </joint>

</robot>