<?xml version="1.0"?>
    <robot name="urdfbot">

      <link name="base_link">
        <visual>        
          <geometry>
            <box size="0.1 0.1 0.1"/>
          </geometry>
        </visual>
      </link>

      <link name="head_link">
        <visual>
        <origin rpy="0 0 0" xyz="0 0 0.1" />
          <geometry>
            <box size="0.1 0.1 0.1"/>
          </geometry>
        </visual>
      </link>

        <joint name="base_link_to_head_link_joint" type="revolute">
            <origin xyz="0 0 0.11" rpy="0 0 0"/>
            <parent link="base_link"/>
            <child link="head_link"/>
            <axis xyz="0 0 1"/>
            <limit effort="100" velocity="1.0" lower="-1.57" upper="1.57"/>
        </joint>

    </robot>




<!-- <?xml version="1.0"?>
<robot name="urdfbot">
        
  <link name="base_link">
    <visual>        
      <geometry>
        <box size="0.1 0.1 0.1"/>
      </geometry>
    </visual>
  </link>

  <link name="head_link1">
    <visual>
    <origin rpy="0 0 0" xyz="0 0 0.1" />
      <geometry>
        <box size="0.1 0.1 0.1"/>
      </geometry>
    </visual>
  </link>

    <joint name="base_link_to_head_link1_joint" type="continuous">
      <origin xyz="0 0 0.11" rpy="0 0 0"/>
      <parent link="base_link"/>
      <child link="head_link1"/>
      <axis xyz="0 0 1"/>
    </joint>

    <link name="head_link2">
    <visual>
    <origin rpy="0 0 0" xyz="0 0.1 0" />
      <geometry>
        <box size="0.1 0.1 0.1"/>
      </geometry>
    </visual>
  </link>

  <joint name="base_link_to_head_link2_joint" type="continuous">
    <origin xyz="0 0 0.11" rpy="0 0 0"/>
    <parent link="base_link"/>
    <child link="head_link2"/>
    <axis xyz="1 0 0"/>
  </joint>


  <link name="head_link3">
    <visual>
    <origin rpy="0 0 0" xyz="0 0 -0.1" />
      <geometry>
        <box size="0.1 0.1 0.1"/>
      </geometry>
    </visual>
  </link>

  <joint name="base_link_to_head_link3_joint" type="fixed">
    <origin rpy="0 0 0" xyz="0 0 -0.11" />
    <parent link="base_link" />
    <child link="head_link3" />
  </joint>

  <link name="head_link4">
    <visual>
    <origin rpy="0 0 0" xyz="0 0 -0.3" />
      <geometry>
        <box size="0.1 0.1 0.1"/>
      </geometry>
    </visual>
  </link>

  <joint name="base_link_to_head_link4_joint" type="revolute">
      <origin xyz="0 0 0" rpy="0 0 0"/>
      <parent link="head_link3"/>
      <child link="head_link4"/>
      <axis xyz="0 0 1"/>
      <limit effort="100" velocity="1.0" lower="-1.57" upper="1.57"/>
  </joint>

  <link name="head_link5">
    <visual>
    <origin rpy="0 0 0" xyz="0.1 0 -0.35" />
      <geometry>
        <box size="0.1 0.1 0.1"/>
      </geometry>
    </visual>
  </link>

  <joint name="base_link_to_head_link5_joint" type="prismatic">
    <origin xyz="0 0 0.0" rpy="0 0 0"/>
    <parent link="head_link4"/>
    <child link="head_link5"/>
    <axis xyz="0 0 1"/>
    <limit effort="100" velocity="0.1" lower="-0.1" upper="0.1"/>
  </joint>
</robot> -->
